<?xml version="1.0" ?>
<!-- =================================================================================== -->
<!-- |    This document was autogenerated by xacro from smart.xacro                    | -->
<!-- |    EDITING THIS FILE BY HAND IS NOT RECOMMENDED                                 | -->
<!-- =================================================================================== -->
<robot name="Smart">
  <!--Car Body-->
  <link name="base_link">
    <collision>
      <origin rpy="0 0 0" xyz="0 0 0.875"/>
      <geometry>
        <box size="2.695 0.68 1.37"/>
      </geometry>
    </collision>
    <visual>
      <origin rpy="0 0 1.5707963417948965" xyz="0.05 0 0.875"/>
      <geometry>
        <mesh filename="package://car_model/meshes/vehicle_body.dae"/>
        <!-- <box size="${base_length} ${base_width} ${base_height}"/> -->
      </geometry>
    </visual>
  </link>
  <joint name="inertial_joint" type="fixed">
    <parent link="base_link"/>
    <child link="main_mass"/>
    <origin rpy="0 0 0" xyz="0 0 0"/>
  </joint>
  <link name="main_mass" type="fixed">
    <inertial>
      <origin rpy="0 0 0" xyz="0 0 0"/>
      <mass value="956"/>
      <inertia ixx="343" ixy="0.000000" ixz="0.000000" iyy="728" iyz="0.000000" izz="772"/>
    </inertial>
  </link>
  <!--Rear Right Wheel-->
  <joint name="rear_right_wheel_joint" type="continuous">
    <parent link="base_link"/>
    <child link="rear_right_wheel_link"/>
    <origin rpy="0 0 0" xyz="-0.945 -0.642 0.3"/>
    <axis xyz="0 1 0"/>
    <dynamics damping="0.1"/>
    <limit effort="100000" velocity="10000"/>
    <joint_properties damping="0.0" friction="0.0"/>
  </joint>
  <link name="rear_right_wheel_link">
    <collision>
      <origin rpy="1.5707963417948965 0 0" xyz="0 0 0"/>
      <geometry>
        <cylinder length="0.165" radius="0.3"/>
      </geometry>
    </collision>
    <visual>
      <origin rpy="0 0 -1.5707963417948965" xyz="0 0 0"/>
      <geometry>
        <mesh filename="package://car_model/meshes/wheel.dae"/>
        <!-- <cylinder length="${rear_tyre_length}" radius="${rear_tyre_r}"/> -->
      </geometry>
    </visual>
    <inertial>
      <origin rpy="0 0 0" xyz="0 0 0"/>
      <mass value="20"/>
      <inertia ixx="0.5" ixy="0.000000" ixz="0.000000" iyy="0.9" iyz="0.000000" izz="0.5"/>
    </inertial>
  </link>
  <!--Rear Left Wheel-->
  <joint name="rear_left_wheel_joint" type="continuous">
    <parent link="base_link"/>
    <child link="rear_left_wheel_link"/>
    <origin rpy="0 0 0" xyz="-0.945 0.642 0.3"/>
    <axis xyz="0 1 0"/>
    <dynamics damping="0.1"/>
    <limit effort="100000" velocity="10000"/>
    <joint_properties damping="0.0" friction="0.0"/>
  </joint>
  <link name="rear_left_wheel_link">
    <collision>
      <origin rpy="1.5707963417948965 0 0" xyz="0 0 0"/>
      <geometry>
        <cylinder length="0.165" radius="0.3"/>
      </geometry>
    </collision>
    <visual>
      <origin rpy="0 0 1.5707963417948965" xyz="0 0 0"/>
      <geometry>
        <mesh filename="package://car_model/meshes/wheel.dae"/>
        <cylinder length="0.165" radius="0.3"/>
      </geometry>
    </visual>
    <inertial>
      <origin rpy="0 0 0" xyz="0 0 0"/>
      <mass value="20"/>
      <inertia ixx="0.5" ixy="0.000000" ixz="0.000000" iyy="0.9" iyz="0.000000" izz="0.5"/>
    </inertial>
  </link>
  <!--Front Right Steering-->
  <joint name="front_right_steering_joint" type="revolute">
    <parent link="base_link"/>
    <child link="front_right_steering_link"/>
    <origin rpy="0 0 0" xyz="0.923 -0.642 0.3"/>
    <axis xyz="0 0 1"/>
    <limit effort="1000000.0" lower="-0.6" upper="0.6" velocity="10000.0"/>
    <dynamics damping="10.0" friction="0.0"/>
  </joint>
  <link name="front_right_steering_link">
    <visual>
      <origin rpy="1.5707963417948965 0 0" xyz="0 0 0"/>
      <geometry>
        <cylinder length="0.01" radius="0.1"/>
      </geometry>
    </visual>
    <inertial>
      <origin rpy="0 0 0" xyz="0 0 0"/>
      <mass value="5"/>
      <inertia ixx="0.012" ixy="0.000000" ixz="0.000000" iyy="0.025" iyz="0.000000" izz="0.012"/>
    </inertial>
  </link>
  <!--Front Right Wheel-->
  <joint name="front_right_wheel_joint" type="continuous">
    <parent link="front_right_steering_link"/>
    <child link="front_right_wheel_link"/>
    <origin rpy="0 0 0" xyz="0 0 0"/>
    <axis xyz="0 1 0"/>
    <dynamics damping="0.1"/>
    <limit effort="1000000" velocity="10000"/>
    <joint_properties damping="0.0" friction="0.0"/>
  </joint>
  <link name="front_right_wheel_link">
    <collision>
      <origin rpy="1.5707963417948965 0 0" xyz="0 0 0"/>
      <geometry>
        <cylinder length="0.165" radius="0.3"/>
      </geometry>
    </collision>
    <visual>
      <origin rpy="0 0 -1.5707963417948965" xyz="0 0 0"/>
      <geometry>
        <mesh filename="package://car_model/meshes/wheel.dae"/>
        <cylinder length="0.165" radius="0.3"/>
      </geometry>
    </visual>
    <inertial>
      <origin rpy="0 0 0" xyz="0 0 0"/>
      <mass value="20"/>
      <inertia ixx="0.5" ixy="0.000000" ixz="0.000000" iyy="0.9" iyz="0.000000" izz="0.5"/>
    </inertial>
  </link>
  <!--Front Left Steering-->
  <joint name="front_left_steering_joint" type="revolute">
    <parent link="base_link"/>
    <child link="front_left_steering_link"/>
    <origin rpy="0 0 0" xyz="0.923 0.642 0.3"/>
    <axis xyz="0 0 1"/>
    <limit effort="1000000.0" lower="-0.6" upper="0.6" velocity="10000.0"/>
    <dynamics damping="10.0" friction="0.0"/>
  </joint>
  <link name="front_left_steering_link">
    <visual>
      <origin rpy="1.5707963417948965 0 0" xyz="0 0 0"/>
      <geometry>
        <cylinder length="0.01" radius="0.1"/>
      </geometry>
    </visual>
    <inertial>
      <origin rpy="0 0 0" xyz="0 0 0"/>
      <mass value="5"/>
      <inertia ixx="0.012" ixy="0.000000" ixz="0.000000" iyy="0.025" iyz="0.000000" izz="0.012"/>
    </inertial>
  </link>
  <!--Front Left Wheel-->
  <joint name="front_left_wheel_joint" type="continuous">
    <parent link="front_left_steering_link"/>
    <child link="front_left_wheel_link"/>
    <origin rpy="0 0 0" xyz="0 0 0"/>
    <axis xyz="0 1 0"/>
    <dynamics damping="0.1"/>
    <limit effort="1000000" velocity="10000"/>
    <joint_properties damping="0.0" friction="0.0"/>
  </joint>
  <link name="front_left_wheel_link">
    <collision>
      <origin rpy="1.5707963417948965 0 0" xyz="0 0 0"/>
      <geometry>
        <cylinder length="0.165" radius="0.3"/>
      </geometry>
    </collision>
    <visual>
      <origin rpy="0 0 1.5707963417948965" xyz="0 0 0"/>
      <geometry>
        <mesh filename="package://car_model/meshes/wheel.dae"/>
        <!-- <cylinder length="${front_tyre_length}" radius="${front_tyre_r}"/> -->
      </geometry>
    </visual>
    <inertial>
      <origin rpy="0 0 0" xyz="0 0 0"/>
      <mass value="20"/>
      <inertia ixx="0.5" ixy="0.000000" ixz="0.000000" iyy="0.9" iyz="0.000000" izz="0.5"/>
    </inertial>
  </link>
  <!-- motors and transmissions for the two rear wheels -->
  <transmission name="tran1">
    <type>transmission_interface/SimpleTransmission</type>
    <joint name="rear_right_wheel_joint">
      <hardwareInterface>hardware_interface/VelocityJointInterface</hardwareInterface>
    </joint>
    <actuator name="motor1">
      <hardwareInterface>hardware_interface/VelocityJointInterface</hardwareInterface>
      <mechanicalReduction>1</mechanicalReduction>
    </actuator>
  </transmission>
  <transmission name="tran2">
    <type>transmission_interface/SimpleTransmission</type>
    <joint name="rear_left_wheel_joint">
      <hardwareInterface>hardware_interface/VelocityJointInterface</hardwareInterface>
    </joint>
    <actuator name="motor2">
      <hardwareInterface>hardware_interface/VelocityJointInterface</hardwareInterface>
      <mechanicalReduction>1</mechanicalReduction>
    </actuator>
  </transmission>
  <!-- EPS and transmissions for the front steering -->
  <transmission name="tran3">
    <type>transmission_interface/SimpleTransmission</type>
    <joint name="front_right_steering_joint">
      <hardwareInterface>hardware_interface/EffortJointInterface</hardwareInterface>
    </joint>
    <actuator name="eps_right">
      <hardwareInterface>hardware_interface/EffortJointInterface</hardwareInterface>
      <mechanicalReduction>1</mechanicalReduction>
      <motorTorqueConstant>1000000</motorTorqueConstant>
    </actuator>
  </transmission>
  <transmission name="tran4">
    <type>transmission_interface/SimpleTransmission</type>
    <joint name="front_left_steering_joint">
      <hardwareInterface>hardware_interface/EffortJointInterface</hardwareInterface>
    </joint>
    <actuator name="eps_left">
      <hardwareInterface>hardware_interface/EffortJointInterface</hardwareInterface>
      <mechanicalReduction>1</mechanicalReduction>
      <motorTorqueConstant>1000000</motorTorqueConstant>
    </actuator>
  </transmission>
  <!-- Friction Parametres -->
  <gazebo reference="rear_right_wheel_link">
    <mu1>10000000</mu1>
    <mu2>10000000</mu2>
    <kp>10000000</kp>
    <kd>1</kd>
    <minDepth>0.01</minDepth>
    <maxVel>100</maxVel>
  </gazebo>
  <gazebo reference="rear_left_wheel_link">
    <mu1>10000000</mu1>
    <mu2>10000000</mu2>
    <kp>10000000</kp>
    <kd>1</kd>
    <minDepth>0.01</minDepth>
    <maxVel>100</maxVel>
  </gazebo>
  <gazebo reference="front_right_wheel_link">
    <mu1>10000000</mu1>
    <mu2>10000000</mu2>
    <kp>10000000</kp>
    <kd>1</kd>
    <minDepth>0.01</minDepth>
    <maxVel>100</maxVel>
  </gazebo>
  <gazebo reference="front_left_wheel_link">
    <mu1>10000000</mu1>
    <mu2>10000000</mu2>
    <kp>10000000</kp>
    <kd>1</kd>
    <minDepth>0.01</minDepth>
    <maxVel>100</maxVel>
  </gazebo>
  <!-- Gazebo Plugins -->
  <gazebo>
    <plugin filename="libgazebo_ros_control.so" name="gazebo_ros_control">
      <robotParam>robot_description</robotParam>
      <robotSimType>gazebo_ros_control/DefaultRobotHWSim</robotSimType>
    </plugin>
  </gazebo>
  <gazebo>
    <plugin filename="libgazebo_ros_joint_state_publisher.so" name="joint_state_publisher">
      <jointName>rear_left_wheel_joint, rear_right_wheel_joint, front_left_steering_joint, front_right_steering_joint, front_right_wheel_joint, front_left_wheel_joint</jointName>
      <updateRate>50.0</updateRate>
      <alwaysOn>true</alwaysOn>
    </plugin>
  </gazebo>
</robot>

